Workbook

Sheet Legend
A1: Bulwark — Map Data Workbook
A2: Companion to Bulwark-Map-GDD.md. Every number here is a design lever; the GDD explains why.
A5: HOW TO USE THIS WORKBOOK
A6: Blue text | B6: Hardcoded input — this is a knob you turn.
A7: Black text | B7: Formula — derived. Do not overwrite.
A8: Green text | B8: Pulls from another sheet.
A9: Yellow fill | B9: Key assumption. Flagged because it was invented, not specified.
A11: EDIT THESE SHEETS
A12: Global_Params | B12: Master tunables. Everything downstream recalculates from here.
A13: Growth_Curve | B13: The 8-wave ring expansion shape. The single most important curve in the design.
A14: Maps | B14: The 9-map sequence: dimensions, primary resource, difficulty.
A15: Factions | B15: The 9 factions: premium resource, harvester yield.
A16: Resources | B16: Value, node yield, respawn rules per resource type.
A17: Harvester_Upgrades | B17: Between-match progression.
A18: Star_Rubric | B18: The 5 wave-star conditions and their thresholds.
A20: DERIVED — DO NOT HAND-EDIT
A21: Wave_Table | B21: 72 rows (9 maps x 8 waves). The build target. Every field is a formula.
A22: Score_Model | B22: Worked example of the map score and the 3.0-star gate.
A24: OPEN ASSUMPTIONS (yellow cells)
A25: Map + faction names | B25: Placeholders. Real names live in Bulwark GDD v2.0 — swap them in.
A26: Map dimensions 2-8 | B26: Only the small (24x16) and large (64x32) maps were specified. Maps 2-8 are interpolated.
A27: All balance numbers | B27: First-pass. They exist so the curve is playable, not because they are right.

Sheet Global_Params
A1: Global Parameters
A2: Master knobs. Wave_Table and Score_Model read from here.
A4: Param | B4: Value | C4: Unit | D4: Notes
A5: STRUCTURE
A6: Maps_In_Campaign | B6: 9 | C6: count | D6: Fixed sequence, all must be cleared.
A7: Waves_Per_Map | B7: 8 | C7: count | D7: One dialog interaction after each wave.
A8: Star_Gate | B8: 3 | C8: stars | D8: Average wave stars needed to unlock the next map.
A9: Max_Stars_Per_Wave | B9: 5 | C9: stars | D9: See Star_Rubric — 5 independent points.
A10: GRID
A11: Map1_Width | B11: 24 | C11: tiles | D11: Smallest map, as specified.
A12: Map1_Height | B12: 16 | C12: tiles | D12: Smallest map, as specified.
A13: Map9_Width | B13: 64 | C13: tiles | D13: Largest map, as specified.
A14: Map9_Height | B14: 32 | C14: tiles | D14: Largest map, as specified.
A15: SPAWNS
A16: Spawn_Setback | B16: 2 | C16: tiles | D16: Spawn sits this far OUTSIDE the current playable edge.
A17: Base_Spawn_Budget | B17: 100 | C17: pts | D17: Wave 1, map 1 enemy budget. Scales by wave ramp x map difficulty.
A18: Wave_Ramp | B18: 0.18 | C18: per wave | D18: Budget growth per wave within a map.
A19: Air_Share_W1 | B19: 0.1 | C19: fraction | D19: Air share of budget at wave 1.
A20: Air_Share_W8 | B20: 0.3 | C20: fraction | D20: Air share of budget at wave 8. Air pressure ramps.
A21: Water_Share | B21: 0.15 | C21: fraction | D21: Flat. Water lanes only exist on water-bearing maps.
A22: ECONOMY
A23: Gold_Per_Resource | B23: 1 | C23: gold/unit | D23: Conversion at map end.
A24: Time_Bonus_Cap | B24: 400 | C24: gold | D24: Max completion-time bonus on a perfect-tempo run.
A25: Par_Time_Per_100_Tiles | B25: 42 | C25: sec | D25: Par time scales with total playable area.
A26: Premium_Ring_Seed | B26: 3 | C26: nodes | D26: Fresh premium nodes seeded in EACH newly-opened ring.
A27: Primary_Respawn_Sec | B27: 75 | C27: sec | D27: Primary respawns in-match. Premium NEVER does.
A28: Uncollectable_Floor | B28: 0.25 | C28: fraction | D28: Min share of map resource that must remain uncollectable.
A29: QUEST / LOYALTY
A30: Quest_First_Wave | B30: 5 | C30: wave | D30: Quest resource appears only in the LAST 4 WAVES, as the map fans out.
A31: Quest_Edge_Band | B31: 0.8 | C31: fraction | D31: Quest nodes spawn beyond this fraction of the playable radius. Far edge only.
A32: Quest_Jitter_Tiles | B32: 4 | C32: tiles | D32: Random scatter on placement. The player cannot pre-plan the route.
A33: Loyalty_Per_Node | B33: 10 | C33: pts | D33: Loyalty awarded per quest node fully harvested.
A34: Rival_Penalty | B34: 0.5 | C34: fraction | D34: Loyalty gained with a faction is LOST with its rival at this rate.
A35: Tech_T1_Threshold | B35: 100 | C35: loyalty | D35: Unlocks the faction's UNIT.
A36: Tech_T2_Threshold | B36: 260 | C36: loyalty | D36: Unlocks the faction's STRUCTURE.
A37: Tech_T3_Threshold | B37: 520 | C37: loyalty | D37: Unlocks the faction's BASE UPGRADE.
A38: QUEST CONTRACT
A39: Decline_Cost | B39: 30 | C39: loyalty | D39: Lost with the giver when you REFUSE their quest. There is no neutral option.
A40: Decline_Rival_Gain | B40: 0.5 | C40: fraction | D40: Refusing a faction PLEASES its rival, at this share of Decline_Cost.
A41: Fulfil_Threshold | B41: 0.6 | C41: fraction | D41: Harvest at least this share of quest nodes or the contract is FAILED.
...

Sheet Growth_Curve
A1: Ring Growth Curve
A2: Linear fraction of the full map that is playable at each wave. Slow-fast-slow: small openings early, the big reveal at waves 4-6, a modest final ring.
A4: Wave | B4: Linear_Fraction | C4: Area_Fraction | D4: Ring_Area_Added | E4: Shape Note
A5: 1 | B5: 0.4 | C5: =B5^2 -> 0.16 | D5: =C5 -> 0.16 | E5: Start pocket. Player can see the walls.
A6: 2 | B6: 0.46 | C6: =B6^2 -> 0.2116 | D6: =C6-C5 -> 0.0516 | E6: Teaser. One new crop, one new spawn angle.
A7: 3 | B7: 0.54 | C7: =B7^2 -> 0.2916 | D7: =C7-C6 -> 0.08 | E7: Primary field opens. Harvester routing starts to matter.
A8: 4 | B8: 0.66 | C8: =B8^2 -> 0.4356 | D8: =C8-C7 -> 0.144 | E8: THE REVEAL. Area nearly doubles. Premium is suddenly far away.
A9: 5 | B9: 0.79 | C9: =B9^2 -> 0.6241 | D9: =C9-C8 -> 0.1885 | E9: Overextension wave. Spawn distance is now real travel time.
A10: 6 | B10: 0.89 | C10: =B10^2 -> 0.7921 | D10: =C10-C9 -> 0.168 | E10: Consolidation. Growth slows, pressure does not.
A11: 7 | B11: 0.96 | C11: =B11^2 -> 0.9216 | D11: =C11-C10 -> 0.1295 | E11: Last sliver. Almost nothing new to grab.
A12: 8 | B12: 1 | C12: =B12^2 -> 1 | D12: =C12-C11 -> 0.0784 | E12: Full map. Final stand, then the map score.
A14: Area_Fraction = Linear_Fraction^2 (both axes scale together, so the map keeps its aspect ratio).
A15: Ring_Area_Added is the design signal: it should peak at wave 4-5. If it is flat, the mid-game is flat.

Sheet Maps
A1: Map Sequence (9 maps, fixed order)
A2: The MAP sets the primary resource. The FACTION sets the premium — see Factions.
A4: Map_ID | B4: Map_Name | C4: Full_W | D4: Full_H | E4: Full_Area | F4: Primary_Resource | G4: Has_Water | H4: Difficulty | I4: Par_Time_Sec | J4: Quest_Giver_Faction | K4: Notes
A5: 1 | B5: Map_01 | C5: =ROUND((Global_Params!$B$11+(Global_Params!$B$13-Global_Params!$B$11)*(A5-1)/(Global_Params!$B$6-1))/2,0)*2 -> 24 | D5: =ROUND((Global_Params!$B$12+(Global_Params!$B$14-Global_Params!$B$12)*(A5-1)/(Global_Params!$B$6-1))/2,0)*2 -> 16 | E5: =C5*D5 -> 384 | F5: Flowers | G5: No | H5: 1 | I5: =ROUND(E5/100*Global_Params!$B$25*8,0) -> 1290 | J5: 3 | K5: Tutorial pressure. Ground only. Teaches the ring.
A6: 2 | B6: Map_02 | C6: =ROUND((Global_Params!$B$11+(Global_Params!$B$13-Global_Params!$B$11)*(A6-1)/(Global_Params!$B$6-1))/2,0)*2 -> 30 | D6: =ROUND((Global_Params!$B$12+(Global_Params!$B$14-Global_Params!$B$12)*(A6-1)/(Global_Params!$B$6-1))/2,0)*2 -> 18 | E6: =C6*D6 -> 540 | F6: Flowers | G6: No | H6: 1.1 | I6: =ROUND(E6/100*Global_Params!$B$25*8,0) -> 1814 | J6: 7 | K6: Air introduced. Same footprint, new axis.
A7: 3 | B7: Map_03 | C7: =ROUND((Global_Params!$B$11+(Global_Params!$B$13-Global_Params!$B$11)*(A7-1)/(Global_Params!$B$6-1))/2,0)*2 -> 34 | D7: =ROUND((Global_Params!$B$12+(Global_Params!$B$14-Global_Params!$B$12)*(A7-1)/(Global_Params!$B$6-1))/2,0)*2 -> 20 | E7: =C7*D7 -> 680 | F7: Minerals | G7: Yes | H7: 1.2 | I7: =ROUND(E7/100*Global_Params!$B$25*8,0) -> 2285 | J7: 1 | K7: Water lanes. Harvester escort becomes a thing.
A8: 4 | B8: Map_04 | C8: =ROUND((Global_Params!$B$11+(Global_Params!$B$13-Global_Params!$B$11)*(A8-1)/(Global_Params!$B$6-1))/2,0)*2 -> 40 | D8: =ROUND((Global_Params!$B$12+(Global_Params!$B$14-Global_Params!$B$12)*(A8-1)/(Global_Params!$B$6-1))/2,0)*2 -> 22 | E8: =C8*D8 -> 880 | F8: Minerals | G8: No | H8: 1.3 | I8: =ROUND(E8/100*Global_Params!$B$25*8,0) -> 2957 | J8: 5 | K8: First mid-size map. The reveal wave lands hard here.
A9: 5 | B9: Map_05 | C9: =ROUND((Global_Params!$B$11+(Global_Params!$B$13-Global_Params!$B$11)*(A9-1)/(Global_Params!$B$6-1))/2,0)*2 -> 44 | D9: =ROUND((Global_Params!$B$12+(Global_Params!$B$14-Global_Params!$B$12)*(A9-1)/(Global_Params!$B$6-1))/2,0)*2 -> 24 | E9: =C9*D9 -> 1056 | F9: Crystals | G9: Yes | H9: 1.4 | I9: =ROUND(E9/100*Global_Params!$B$25*8,0) -> 3548 | J9: 9 | K9: Crystals: high value, slow harvest. Tempo trap.
A10: 6 | B10: Map_06 | C10: =ROUND((Global_Params!$B$11+(Global_Params!$B$13-Global_Params!$B$11)*(A10-1)/(Global_Params!$B$6-1))/2,0)*2 -> 50 | D10: =ROUND((Global_Params!$B$12+(Global_Params!$B$14-Global_Params!$B$12)*(A10-1)/(Global_Params!$B$6-1))/2,0)*2 -> 26 | E10: =C10*D10 -> 1300 | F10: Flowers | G10: Yes | H10: 1.5 | I10: =ROUND(E10/100*Global_Params!$B$25*8,0) -> 4368 | J10: 2 | K10: Three-way spawn pressure.
A11: 7 | B11: Map_07 | C11: =ROUND((Global_Params!$B$11+(Global_Params!$B$13-Global_Params!$B$11)*(A11-1)/(Global_Params!$B$6-1))/2,0)*2 -> 54 | D11: =ROUND((Global_Params!$B$12+(Global_Params!$B$14-Global_Params!$B$12)*(A11-1)/(Global_Params!$B$6-1))/2,0)*2 -> 28 | E11: =C11*D11 -> 1512 | F11: Minerals | G11: No | H11: 1.6 | I11: =ROUND(E11/100*Global_Params!$B$25*8,0) -> 5080 | J11: 8 | K11: Widest ground field. Routing puzzle.
A12: 8 | B12: Map_08 | C12: =ROUND((Global_Params!$B$11+(Global_Params!$B$13-Global_Params!$B$11)*(A12-1)/(Global_Params!$B$6-1))/2,0)*2 -> 60 | D12: =ROUND((Global_Params!$B$12+(Global_Params!$B$14-Global_Params!$B$12)*(A12-1)/(Global_Params!$B$6-1))/2,0)*2 -> 30 | E12: =C12*D12 -> 1800 | F12: Crystals | G12: Yes | H12: 1.7 | I12: =ROUND(E12/100*Global_Params!$B$25*8,0) -> 6048 | J12: 4 | K12: Premium is deliberately stranded far out.
A13: 9 | B13: Map_09 | C13: =ROUND((Global_Params!$B$11+(Global_Params!$B$13-Global_Params!$B$11)*(A13-1)/(Global_Params!$B$6-1))/2,0)*2 -> 64 | D13: =ROUND((Global_Params!$B$12+(Global_Params!$B$14-Global_Params!$B$12)*(A13-1)/(Global_Params!$B$6-1))/2,0)*2 -> 32 | E13: =C13*D13 -> 2048 | F13: Crystals | G13: Yes | H13: 1.8 | I13: =ROUND(E13/100*Global_Params!$B$25*8,0) -> 6881 | J13: 6 | K13: Full 64x32. Everything at once.
A15: Quest_Giver_Faction: whose loyalty the map's quest resource earns. Each map serves a different faction's quest.
A16: Par_Time_Sec is the WHOLE map (8 waves). Difficulty scales spawn budget. Full_W/Full_H interpolated — only maps 1 and 9 specified.

Sheet Factions
A1: Factions (9) — Premium Resource & Harvester Profile
A2: Faction names are placeholders; pull the real nine from Bulwark GDD v2.0.
A4: Faction_ID | B4: Faction_Name | C4: Premium_Resource | D4: Premium_Secondary | E4: Rival_Faction | F4: Yield_Mult | G4: Harvester_Base_Capacity | H4: Harvester_Base_Speed | I4: Harvester_Base_HP | J4: Profile
A5: 1 | B5: Faction_01 | C5: Crystals | D5: Minerals | E5: 2 | F5: 1 | G5: 40 | H5: 3 | I5: 120 | J5: Baseline. The tuning reference.
A6: 2 | B6: Faction_02 | C6: Flowers | D6: Crystals | E6: 1 | F6: 1.15 | G6: 32 | H6: 3.6 | I6: 90 | J6: Fast, fragile. Grabs premium and runs.
A7: 3 | B7: Faction_03 | C7: Minerals | D7: Flowers | E7: 4 | F7: 0.9 | G7: 55 | H7: 2.2 | I7: 170 | J7: Slow tank. Sits in the field and eats hits.
A8: 4 | B8: Faction_04 | C8: Crystals | D8: Flowers | E8: 3 | F8: 1.05 | G8: 38 | H8: 3.2 | I8: 110 | J8: Generalist with a premium bias.
A9: 5 | B9: Faction_05 | C9: Flowers | D9: Minerals | E9: 6 | F9: 1.2 | G9: 28 | H9: 3.8 | I9: 80 | J9: Highest yield, lowest survivability. Greed faction.
A10: 6 | B10: Faction_06 | C10: Minerals | D10: Crystals | E10: 5 | F10: 0.95 | G10: 50 | H10: 2.5 | I10: 155 | J10: Escort-dependent.
A11: 7 | B11: Faction_07 | C11: Crystals | D11: Minerals | E11: 8 | F11: 1.1 | G11: 36 | H11: 3.1 | I11: 115 | J11: Two harvesters, half capacity each (see GDD).
A12: 8 | B12: Faction_08 | C12: Flowers | D12: Crystals | E12: 7 | F12: 1 | G12: 42 | H12: 2.9 | I12: 125 | J12: Balanced.
A13: 9 | B13: Faction_09 | C13: Minerals | D13: Flowers | E13: none | F13: 0.85 | G13: 60 | H13: 2 | I13: 190 | J13: UNALIGNED. No rival — the diplomat. Can court everyone.
A15: CLASH FIX: if a faction's premium == the map's primary, the premium SWAPS to Premium_Secondary.
A16: Premium_Secondary must never equal Premium_Resource. That single constraint guarantees the swap never re-collides,
A17: which guarantees all THREE resource types are always in play with three distinct roles. See Resource_Roles.
A18: RIVALS are reciprocal pairs: (1,2) (3,4) (5,6) (7,8). Faction 09 is unaligned and has no rival.
A19: An odd faction count means someone has to be the diplomat. Use it — 09 is the only faction that can max every tech tree.

Sheet Resources
A1: Resource Types
A2: Two tiers per map: the map's primary, and the faction's premium.
A4: Resource | B4: Tier | C4: Value_Per_Unit | D4: Units_Per_Node | E4: Harvest_Sec_Per_Node | F4: Respawns_In_Match | G4: Respawn_Sec | H4: Notes
A5: Flowers | B5: Primary | C5: 4 | D5: 25 | E5: 6 | F5: Yes | G5: =Global_Params!$B$26 -> 3 | H5: Cheap, fast, everywhere. The safe income.
A6: Minerals | B6: Primary | C6: 6 | D6: 20 | E6: 9 | F6: Yes | G6: =Global_Params!$B$26 -> 3 | H6: Slower to pull, better per node.
A7: Crystals | B7: Primary | C7: 9 | D7: 14 | E7: 14 | F7: Yes | G7: =Global_Params!$B$26*1.4 -> 4.2 | H7: Tempo trap: high value, brutal harvest time.
A8: Flowers | B8: Premium | C8: 14 | D8: 18 | E8: 9 | F8: No | G8: n/a | H8: Premium NEVER respawns. Seeded fresh per ring only.
A9: Minerals | B9: Premium | C9: 20 | D9: 15 | E9: 13 | F9: No | G9: n/a | H9: Premium NEVER respawns. Seeded fresh per ring only.
A10: Crystals | B10: Premium | C10: 30 | D10: 10 | E10: 20 | F10: No | G10: n/a | H10: The greed prize. Deep in the new ring, every time.
A12: Premium/Primary value ratio is ~3.3x. That ratio IS the greed dial — raise it and players overextend.

Sheet Harvester_Upgrades
A1: Harvester Upgrades (between matches)
A2: Bought with gold from the map score.
A4: Level | B4: Gold_Cost | C4: Cumulative_Gold | D4: Capacity_Mult | E4: Speed_Mult | F4: HP_Mult | G4: Unlock | H4: Notes
A5: 1 | B5: 0 | C5: =B5 -> 0 | D5: 1 | E5: 1 | F5: 1 | G5: — | H5: Starting harvester.
A6: 2 | B6: 600 | C6: =C5+B6 -> 600 | D6: 1.2 | E6: 1.05 | F6: 1.15 | G6: — | H6: Pure throughput.
A7: 3 | B7: 1500 | C7: =C6+B7 -> 2100 | D7: 1.4 | E7: 1.15 | F7: 1.3 | G7: Auto-return at 90% | H7: Reduces micro.
A8: 4 | B8: 3200 | C8: =C7+B8 -> 5300 | D8: 1.65 | E8: 1.25 | F8: 1.55 | G8: 2nd harvester | H8: The economy inflection. Two routes at once.
A9: 5 | B9: 6000 | C9: =C8+B9 -> 11300 | D9: 2 | E9: 1.4 | F9: 1.9 | G9: Premium fast-harvest | H9: Endgame greed enabler.
A11: Cumulative cost to max = 11,300 gold. Sanity check it against 9 maps of net score in Score_Model.

Sheet Star_Rubric
A1: Wave Star Rubric — 5 independent points
A2: Wave stars average across the 8 waves. Average >= 3.0 unlocks the next map.
A4: Star | B4: Condition | C4: Threshold | D4: Pressures | E4: Design Intent
A5: 1 | B5: Core takes no damage this wave | C5: 0 leaks | D5: Defense | E5: The floor. Bad defense costs a star immediately.
A6: 2 | B6: Zero harvesters lost this wave | C6: 0 losses | D6: Don't overextend | E6: Directly opposes star 4. That tension is the game.
A7: 3 | B7: Primary quota met | C7: 60% of primary in-ring | D7: Baseline harvesting | E7: Achievable while playing safe. Guarantees a 3-star floor.
A8: 4 | B8: Premium claimed in the new ring | C8: All ring premium nodes | D8: Greed | E8: Fresh premium seeded every ring, so this star is ALWAYS live.
A9: 5 | B9: Wave cleared under par time | C9: <= wave par | D9: Tempo | E9: Opposes farming the primary respawn. Forces the player to leave value behind.
A11: GATE MATH
A12: 3 stars = held the line and harvested competently. 4-5 = took the ring risk and got out clean.
A13: Gate is AVERAGE >= 3.0 across 8 waves, so a player can eat one bad wave without restarting the map.
A14: Worst survivable run: seven 3-star waves + one 0-star wave = 2.63. FAILS. One disaster is not survivable.
A15: Seven 3-star waves + one 5-star wave = 3.25. PASSES. So a single greedy wave rescues a mediocre run.
A16: That asymmetry is intentional: it pushes players to take the greed star at least once per map.

Sheet Wave_Table
A1: Wave Table — 72 rows (9 maps x 8 waves)
A2: THE BUILD TARGET. Every cell is derived. Change Global_Params / Growth_Curve / Maps and this recalculates.
A4: Map_ID | B4: Wave | C4: Playable_W | D4: Playable_H | E4: Playable_Area | F4: Ring_Area_Added | G4: Spawn_Dist_X | H4: Spawn_Dist_Y | I4: Side_Focus | J4: Spawn_Budget | K4: Ground_Pts | L4: Air_Pts | M4: Water_Pts | N4: Primary_Nodes | O4: Premium_Nodes | P4: Primary_Quota_Nodes | Q4: Wave_Par_Sec | R4: Map_Primary | S4: Linear_Fraction | T4: Quest_Nodes | U4: Quest_Side | V4: Quest_Band_Min_X | W4: Quest_Band_Min_Y | X4: Quest_Jitter | Y4: Loyalty_Available
A5: 1 | B5: 1 | C5: =MIN(Maps!$C$5-2,ROUND(Maps!$C$5*Growth_Curve!$B$5/2,0)*2) -> 10 | D5: =MIN(Maps!$D$5,ROUND(Maps!$D$5*Growth_Curve!$B$5/2,0)*2) -> 6 | E5: =C5*D5 -> 60 | F5: =E5 -> 60 | G5: =ROUND(C5/2,0)+Global_Params!$B$16 -> 7 | H5: =ROUND(D5/2,0)+Global_Params!$B$16 -> 5 | I5: L | J5: =ROUND(Global_Params!$B$17*(1+Global_Params!$B$18*(B5-1))*Maps!$H$5,0) -> 100 | K5: =J5-L5-M5 -> 90 | L5: =ROUND(J5*(Global_Params!$B$19+(Global_Params!$B$20-Global_Params!$B$19)*(B5-1)/(Global_Params!$B$7-1)),0) -> 10 | M5: =ROUND(J5*IF(Maps!$G$5="Yes",Global_Params!$B$21,0),0) -> 0 | N5: =MAX(2,ROUND(E5/45,0)) -> 2 | O5: =1 -> 1 | P5: =ROUND(N5*0.6,0) -> 1 | Q5: =ROUND(E5/100*Global_Params!$B$25,0) -> 25 | R5: =Maps!$F$5 -> Flowers | S5: =Growth_Curve!$B$5 -> 0.4 | T5: =IF(B5<Global_Params!$B$30,0,MAX(1,ROUND(E5/260,0))) -> 0 | U5: =IF(T5=0,"-","R") -> - | V5: =IF(T5=0,0,ROUND(C5/2*Global_Params!$B$31,0)) -> 0 | W5: =IF(T5=0,0,ROUND(D5/2*Global_Params!$B$31,0)) -> 0 | X5: =IF(T5=0,0,Global_Params!$B$32) -> 0 | Y5: =T5*Global_Params!$B$33 -> 0
A6: 1 | B6: 2 | C6: =MIN(Maps!$C$5-2,MAX(C5+2,ROUND(Maps!$C$5*Growth_Curve!$B$6/2,0)*2)) -> 12 | D6: =MIN(Maps!$D$5,MAX(D5,ROUND(Maps!$D$5*Growth_Curve!$B$6/2,0)*2)) -> 8 | E6: =C6*D6 -> 96 | F6: =E6-E5 -> 36 | G6: =ROUND(C6/2,0)+Global_Params!$B$16 -> 8 | H6: =ROUND(D6/2,0)+Global_Params!$B$16 -> 6 | I6: R | J6: =ROUND(Global_Params!$B$17*(1+Global_Params!$B$18*(B6-1))*Maps!$H$5,0) -> 118 | K6: =J6-L6-M6 -> 103 | L6: =ROUND(J6*(Global_Params!$B$19+(Global_Params!$B$20-Global_Params!$B$19)*(B6-1)/(Global_Params!$B$7-1)),0) -> 15 | M6: =ROUND(J6*IF(Maps!$G$5="Yes",Global_Params!$B$21,0),0) -> 0 | N6: =MAX(2,ROUND(E6/45,0)) -> 2 | O6: =MAX(1,MIN(Global_Params!$B$26,ROUND(F6/50,0))) -> 1 | P6: =ROUND(N6*0.6,0) -> 1 | Q6: =ROUND(E6/100*Global_Params!$B$25,0) -> 40 | R6: =Maps!$F$5 -> Flowers | S6: =Growth_Curve!$B$6 -> 0.46 | T6: =IF(B6<Global_Params!$B$30,0,MAX(1,ROUND(E6/260,0))) -> 0 | U6: =IF(T6=0,"-","L") -> - | V6: =IF(T6=0,0,ROUND(C6/2*Global_Params!$B$31,0)) -> 0 | W6: =IF(T6=0,0,ROUND(D6/2*Global_Params!$B$31,0)) -> 0 | X6: =IF(T6=0,0,Global_Params!$B$32) -> 0 | Y6: =T6*Global_Params!$B$33 -> 0
A7: 1 | B7: 3 | C7: =MIN(Maps!$C$5-2,MAX(C6+2,ROUND(Maps!$C$5*Growth_Curve!$B$7/2,0)*2)) -> 14 | D7: =MIN(Maps!$D$5,MAX(D6,ROUND(Maps!$D$5*Growth_Curve!$B$7/2,0)*2)) -> 8 | E7: =C7*D7 -> 112 | F7: =E7-E6 -> 16 | G7: =ROUND(C7/2,0)+Global_Params!$B$16 -> 9 | H7: =ROUND(D7/2,0)+Global_Params!$B$16 -> 6 | I7: L | J7: =ROUND(Global_Params!$B$17*(1+Global_Params!$B$18*(B7-1))*Maps!$H$5,0) -> 136 | K7: =J7-L7-M7 -> 115 | L7: =ROUND(J7*(Global_Params!$B$19+(Global_Params!$B$20-Global_Params!$B$19)*(B7-1)/(Global_Params!$B$7-1)),0) -> 21 | M7: =ROUND(J7*IF(Maps!$G$5="Yes",Global_Params!$B$21,0),0) -> 0 | N7: =MAX(2,ROUND(E7/45,0)) -> 2 | O7: =MAX(1,MIN(Global_Params!$B$26,ROUND(F7/50,0))) -> 1 | P7: =ROUND(N7*0.6,0) -> 1 | Q7: =ROUND(E7/100*Global_Params!$B$25,0) -> 47 | R7: =Maps!$F$5 -> Flowers | S7: =Growth_Curve!$B$7 -> 0.54 | T7: =IF(B7<Global_Params!$B$30,0,MAX(1,ROUND(E7/260,0))) -> 0 | U7: =IF(T7=0,"-","R") -> - | V7: =IF(T7=0,0,ROUND(C7/2*Global_Params!$B$31,0)) -> 0 | W7: =IF(T7=0,0,ROUND(D7/2*Global_Params!$B$31,0)) -> 0 | X7: =IF(T7=0,0,Global_Params!$B$32) -> 0 | Y7: =T7*Global_Params!$B$33 -> 0
A8: 1 | B8: 4 | C8: =MIN(Maps!$C$5-2,MAX(C7+2,ROUND(Maps!$C$5*Growth_Curve!$B$8/2,0)*2)) -> 16 | D8: =MIN(Maps!$D$5,MAX(D7,ROUND(Maps!$D$5*Growth_Curve!$B$8/2,0)*2)) -> 10 | E8: =C8*D8 -> 160 | F8: =E8-E7 -> 48 | G8: =ROUND(C8/2,0)+Global_Params!$B$16 -> 10 | H8: =ROUND(D8/2,0)+Global_Params!$B$16 -> 7 | I8: R | J8: =ROUND(Global_Params!$B$17*(1+Global_Params!$B$18*(B8-1))*Maps!$H$5,0) -> 154 | K8: =J8-L8-M8 -> 125 | L8: =ROUND(J8*(Global_Params!$B$19+(Global_Params!$B$20-Global_Params!$B$19)*(B8-1)/(Global_Params!$B$7-1)),0) -> 29 | M8: =ROUND(J8*IF(Maps!$G$5="Yes",Global_Params!$B$21,0),0) -> 0 | N8: =MAX(2,ROUND(E8/45,0)) -> 4 | O8: =MAX(1,MIN(Global_Params!$B$26,ROUND(F8/50,0))) -> 1 | P8: =ROUND(N8*0.6,0) -> 2 | Q8: =ROUND(E8/100*Global_Params!$B$25,0) -> 67 | R8: =Maps!$F$5 -> Flowers | S8: =Growth_Curve!$B$8 -> 0.66 | T8: =IF(B8<Global_Params!$B$30,0,MAX(1,ROUND(E8/260,0))) -> 0 | U8: =IF(T8=0,"-","L") -> - | V8: =IF(T8=0,0,ROUND(C8/2*Global_Params!$B$31,0)) -> 0 | W8: =IF(T8=0,0,ROUND(D8/2*Global_Params!$B$31,0)) -> 0 | X8: =IF(T8=0,0,Global_Params!$B$32) -> 0 | Y8: =T8*Global_Params!$B$33 -> 0
A9: 1 | B9: 5 | C9: =MIN(Maps!$C$5-2,MAX(C8+2,ROUND(Maps!$C$5*Growth_Curve!$B$9/2,0)*2)) -> 18 | D9: =MIN(Maps!$D$5,MAX(D8,ROUND(Maps!$D$5*Growth_Curve!$B$9/2,0)*2)) -> 12 | E9: =C9*D9 -> 216 | F9: =E9-E8 -> 56 | G9: =ROUND(C9/2,0)+Global_Params!$B$16 -> 11 | H9: =ROUND(D9/2,0)+Global_Params!$B$16 -> 8 | I9: L | J9: =ROUND(Global_Params!$B$17*(1+Global_Params!$B$18*(B9-1))*Maps!$H$5,0) -> 172 | K9: =J9-L9-M9 -> 135 | L9: =ROUND(J9*(Global_Params!$B$19+(Global_Params!$B$20-Global_Params!$B$19)*(B9-1)/(Global_Params!$B$7-1)),0) -> 37 | M9: =ROUND(J9*IF(Maps!$G$5="Yes",Global_Params!$B$21,0),0) -> 0 | N9: =MAX(2,ROUND(E9/45,0)) -> 5 | O9: =MAX(1,MIN(Global_Params!$B$26,ROUND(F9/50,0))) -> 1 | P9: =ROUND(N9*0.6,0) -> 3 | Q9: =ROUND(E9/100*Global_Params!$B$25,0) -> 91 | R9: =Maps!$F$5 -> Flowers | S9: =Growth_Curve!$B$9 -> 0.79 | T9: =IF(B9<Global_Params!$B$30,0,MAX(1,ROUND(E9/260,0))) -> 1 | U9: =IF(T9=0,"-","R") -> R | V9: =IF(T9=0,0,ROUND(C9/2*Global_Params!$B$31,0)) -> 7 | W9: =IF(T9=0,0,ROUND(D9/2*Global_Params!$B$31,0)) -> 5 | X9: =IF(T9=0,0,Global_Params!$B$32) -> 4 | Y9: =T9*Global_Params!$B$33 -> 10
A10: 1 | B10: 6 | C10: =MIN(Maps!$C$5-2,MAX(C9+2,ROUND(Maps!$C$5*Growth_Curve!$B$10/2,0)*2)) -> 22 | D10: =MIN(Maps!$D$5,MAX(D9,ROUND(Maps!$D$5*Growth_Curve!$B$10/2,0)*2)) -> 14 | E10: =C10*D10 -> 308 | F10: =E10-E9 -> 92 | G10: =ROUND(C10/2,0)+Global_Params!$B$16 -> 13 | H10: =ROUND(D10/2,0)+Global_Params!$B$16 -> 9 | I10: R | J10: =ROUND(Global_Params!$B$17*(1+Global_Params!$B$18*(B10-1))*Maps!$H$5,0) -> 190 | K10: =J10-L10-M10 -> 144 | L10: =ROUND(J10*(Global_Params!$B$19+(Global_Params!$B$20-Global_Params!$B$19)*(B10-1)/(Global_Params!$B$7-1)),0) -> 46 | M10: =ROUND(J10*IF(Maps!$G$5="Yes",Global_Params!$B$21,0),0) -> 0 | N10: =MAX(2,ROUND(E10/45,0)) -> 7 | O10: =MAX(1,MIN(Global_Params!$B$26,ROUND(F10/50,0))) -> 2 | P10: =ROUND(N10*0.6,0) -> 4 | Q10: =ROUND(E10/100*Global_Params!$B$25,0) -> 129 | R10: =Maps!$F$5 -> Flowers | S10: =Growth_Curve!$B$10 -> 0.89 | T10: =IF(B10<Global_Params!$B$30,0,MAX(1,ROUND(E10/260,0))) -> 1 | U10: =IF(T10=0,"-","L") -> L | V10: =IF(T10=0,0,ROUND(C10/2*Global_Params!$B$31,0)) -> 9 | W10: =IF(T10=0,0,ROUND(D10/2*Global_Params!$B$31,0)) -> 6 | X10: =IF(T10=0,0,Global_Params!$B$32) -> 4 | Y10: =T10*Global_Params!$B$33 -> 10
A11: 1 | B11: 7 | C11: =MIN(Maps!$C$5-2,MAX(C10+2,ROUND(Maps!$C$5*Growth_Curve!$B$11/2,0)*2)) -> 22 | D11: =MIN(Maps!$D$5,MAX(D10,ROUND(Maps!$D$5*Growth_Curve!$B$11/2,0)*2)) -> 16 | E11: =C11*D11 -> 352 | F11: =E11-E10 -> 44 | G11: =ROUND(C11/2,0)+Global_Params!$B$16 -> 13 | H11: =ROUND(D11/2,0)+Global_Params!$B$16 -> 10 | I11: T | J11: =ROUND(Global_Params!$B$17*(1+Global_Params!$B$18*(B11-1))*Maps!$H$5,0) -> 208 | K11: =J11-L11-M11 -> 152 | L11: =ROUND(J11*(Global_Params!$B$19+(Global_Params!$B$20-Global_Params!$B$19)*(B11-1)/(Global_Params!$B$7-1)),0) -> 56 | M11: =ROUND(J11*IF(Maps!$G$5="Yes",Global_Params!$B$21,0),0) -> 0 | N11: =MAX(2,ROUND(E11/45,0)) -> 8 | O11: =MAX(1,MIN(Global_Params!$B$26,ROUND(F11/50,0))) -> 1 | P11: =ROUND(N11*0.6,0) -> 5 | Q11: =ROUND(E11/100*Global_Params!$B$25,0) -> 148 | R11: =Maps!$F$5 -> Flowers | S11: =Growth_Curve!$B$11 -> 0.96 | T11: =IF(B11<Global_Params!$B$30,0,MAX(1,ROUND(E11/260,0))) -> 1 | U11: =IF(T11=0,"-","B") -> B | V11: =IF(T11=0,0,ROUND(C11/2*Global_Params!$B$31,0)) -> 9 | W11: =IF(T11=0,0,ROUND(D11/2*Global_Params!$B$31,0)) -> 6 | X11: =IF(T11=0,0,Global_Params!$B$32) -> 4 | Y11: =T11*Global_Params!$B$33 -> 10
A12: 1 | B12: 8 | C12: =Maps!$C$5 -> 24 | D12: =Maps!$D$5 -> 16 | E12: =C12*D12 -> 384 | F12: =E12-E11 -> 32 | G12: =ROUND(C12/2,0)+Global_Params!$B$16 -> 14 | H12: =ROUND(D12/2,0)+Global_Params!$B$16 -> 10 | I12: B | J12: =ROUND(Global_Params!$B$17*(1+Global_Params!$B$18*(B12-1))*Maps!$H$5,0) -> 226 | K12: =J12-L12-M12 -> 158 | L12: =ROUND(J12*(Global_Params!$B$19+(Global_Params!$B$20-Global_Params!$B$19)*(B12-1)/(Global_Params!$B$7-1)),0) -> 68 | M12: =ROUND(J12*IF(Maps!$G$5="Yes",Global_Params!$B$21,0),0) -> 0 | N12: =MAX(2,ROUND(E12/45,0)) -> 9 | O12: =MAX(1,MIN(Global_Params!$B$26,ROUND(F12/50,0))) -> 1 | P12: =ROUND(N12*0.6,0) -> 5 | Q12: =ROUND(E12/100*Global_Params!$B$25,0) -> 161 | R12: =Maps!$F$5 -> Flowers | S12: =Growth_Curve!$B$12 -> 1 | T12: =IF(B12<Global_Params!$B$30,0,MAX(1,ROUND(E12/260,0))) -> 1 | U12: =IF(T12=0,"-","T") -> T | V12: =IF(T12=0,0,ROUND(C12/2*Global_Params!$B$31,0)) -> 10 | W12: =IF(T12=0,0,ROUND(D12/2*Global_Params!$B$31,0)) -> 6 | X12: =IF(T12=0,0,Global_Params!$B$32) -> 4 | Y12: =T12*Global_Params!$B$33 -> 10
A13: 2 | B13: 1 | C13: =MIN(Maps!$C$6-2,ROUND(Maps!$C$6*Growth_Curve!$B$5/2,0)*2) -> 12 | D13: =MIN(Maps!$D$6,ROUND(Maps!$D$6*Growth_Curve!$B$5/2,0)*2) -> 8 | E13: =C13*D13 -> 96 | F13: =E13 -> 96 | G13: =ROUND(C13/2,0)+Global_Params!$B$16 -> 8 | H13: =ROUND(D13/2,0)+Global_Params!$B$16 -> 6 | I13: R | J13: =ROUND(Global_Params!$B$17*(1+Global_Params!$B$18*(B13-1))*Maps!$H$6,0) -> 110 | K13: =J13-L13-M13 -> 99 | L13: =ROUND(J13*(Global_Params!$B$19+(Global_Params!$B$20-Global_Params!$B$19)*(B13-1)/(Global_Params!$B$7-1)),0) -> 11 | M13: =ROUND(J13*IF(Maps!$G$6="Yes",Global_Params!$B$21,0),0) -> 0 | N13: =MAX(2,ROUND(E13/45,0)) -> 2 | O13: =1 -> 1 | P13: =ROUND(N13*0.6,0) -> 1 | Q13: =ROUND(E13/100*Global_Params!$B$25,0) -> 40 | R13: =Maps!$F$6 -> Flowers | S13: =Growth_Curve!$B$5 -> 0.4 | T13: =IF(B13<Global_Params!$B$30,0,MAX(1,ROUND(E13/260,0))) -> 0 | U13: =IF(T13=0,"-","L") -> - | V13: =IF(T13=0,0,ROUND(C13/2*Global_Params!$B$31,0)) -> 0 | W13: =IF(T13=0,0,ROUND(D13/2*Global_Params!$B$31,0)) -> 0 | X13: =IF(T13=0,0,Global_Params!$B$32) -> 0 | Y13: =T13*Global_Params!$B$33 -> 0
A14: 2 | B14: 2 | C14: =MIN(Maps!$C$6-2,MAX(C13+2,ROUND(Maps!$C$6*Growth_Curve!$B$6/2,0)*2)) -> 14 | D14: =MIN(Maps!$D$6,MAX(D13,ROUND(Maps!$D$6*Growth_Curve!$B$6/2,0)*2)) -> 8 | E14: =C14*D14 -> 112 | F14: =E14-E13 -> 16 | G14: =ROUND(C14/2,0)+Global_Params!$B$16 -> 9 | H14: =ROUND(D14/2,0)+Global_Params!$B$16 -> 6 | I14: L | J14: =ROUND(Global_Params!$B$17*(1+Global_Params!$B$18*(B14-1))*Maps!$H$6,0) -> 130 | K14: =J14-L14-M14 -> 113 | L14: =ROUND(J14*(Global_Params!$B$19+(Global_Params!$B$20-Global_Params!$B$19)*(B14-1)/(Global_Params!$B$7-1)),0) -> 17 | M14: =ROUND(J14*IF(Maps!$G$6="Yes",Global_Params!$B$21,0),0) -> 0 | N14: =MAX(2,ROUND(E14/45,0)) -> 2 | O14: =MAX(1,MIN(Global_Params!$B$26,ROUND(F14/50,0))) -> 1 | P14: =ROUND(N14*0.6,0) -> 1 | Q14: =ROUND(E14/100*Global_Params!$B$25,0) -> 47 | R14: =Maps!$F$6 -> Flowers | S14: =Growth_Curve!$B$6 -> 0.46 | T14: =IF(B14<Global_Params!$B$30,0,MAX(1,ROUND(E14/260,0))) -> 0 | U14: =IF(T14=0,"-","R") -> - | V14: =IF(T14=0,0,ROUND(C14/2*Global_Params!$B$31,0)) -> 0 | W14: =IF(T14=0,0,ROUND(D14/2*Global_Params!$B$31,0)) -> 0 | X14: =IF(T14=0,0,Global_Params!$B$32) -> 0 | Y14: =T14*Global_Params!$B$33 -> 0
A15: 2 | B15: 3 | C15: =MIN(Maps!$C$6-2,MAX(C14+2,ROUND(Maps!$C$6*Growth_Curve!$B$7/2,0)*2)) -> 16 | D15: =MIN(Maps!$D$6,MAX(D14,ROUND(Maps!$D$6*Growth_Curve!$B$7/2,0)*2)) -> 10 | E15: =C15*D15 -> 160 | F15: =E15-E14 -> 48 | G15: =ROUND(C15/2,0)+Global_Params!$B$16 -> 10 | H15: =ROUND(D15/2,0)+Global_Params!$B$16 -> 7 | I15: R | J15: =ROUND(Global_Params!$B$17*(1+Global_Params!$B$18*(B15-1))*Maps!$H$6,0) -> 150 | K15: =J15-L15-M15 -> 126 | L15: =ROUND(J15*(Global_Params!$B$19+(Global_Params!$B$20-Global_Params!$B$19)*(B15-1)/(Global_Params!$B$7-1)),0) -> 24 | M15: =ROUND(J15*IF(Maps!$G$6="Yes",Global_Params!$B$21,0),0) -> 0 | N15: =MAX(2,ROUND(E15/45,0)) -> 4 | O15: =MAX(1,MIN(Global_Params!$B$26,ROUND(F15/50,0))) -> 1 | P15: =ROUND(N15*0.6,0) -> 2 | Q15: =ROUND(E15/100*Global_Params!$B$25,0) -> 67 | R15: =Maps!$F$6 -> Flowers | S15: =Growth_Curve!$B$7 -> 0.54 | T15: =IF(B15<Global_Params!$B$30,0,MAX(1,ROUND(E15/260,0))) -> 0 | U15: =IF(T15=0,"-","L") -> - | V15: =IF(T15=0,0,ROUND(C15/2*Global_Params!$B$31,0)) -> 0 | W15: =IF(T15=0,0,ROUND(D15/2*Global_Params!$B$31,0)) -> 0 | X15: =IF(T15=0,0,Global_Params!$B$32) -> 0 | Y15: =T15*Global_Params!$B$33 -> 0
A16: 2 | B16: 4 | C16: =MIN(Maps!$C$6-2,MAX(C15+2,ROUND(Maps!$C$6*Growth_Curve!$B$8/2,0)*2)) -> 20 | D16: =MIN(Maps!$D$6,MAX(D15,ROUND(Maps!$D$6*Growth_Curve!$B$8/2,0)*2)) -> 12 | E16: =C16*D16 -> 240 | F16: =E16-E15 -> 80 | G16: =ROUND(C16/2,0)+Global_Params!$B$16 -> 12 | H16: =ROUND(D16/2,0)+Global_Params!$B$16 -> 8 | I16: L | J16: =ROUND(Global_Params!$B$17*(1+Global_Params!$B$18*(B16-1))*Maps!$H$6,0) -> 169 | K16: =J16-L16-M16 -> 138 | L16: =ROUND(J16*(Global_Params!$B$19+(Global_Params!$B$20-Global_Params!$B$19)*(B16-1)/(Global_Params!$B$7-1)),0) -> 31 | M16: =ROUND(J16*IF(Maps!$G$6="Yes",Global_Params!$B$21,0),0) -> 0 | N16: =MAX(2,ROUND(E16/45,0)) -> 5 | O16: =MAX(1,MIN(Global_Params!$B$26,ROUND(F16/50,0))) -> 2 | P16: =ROUND(N16*0.6,0) -> 3 | Q16: =ROUND(E16/100*Global_Params!$B$25,0) -> 101 | R16: =Maps!$F$6 -> Flowers | S16: =Growth_Curve!$B$8 -> 0.66 | T16: =IF(B16<Global_Params!$B$30,0,MAX(1,ROUND(E16/260,0))) -> 0 | U16: =IF(T16=0,"-","R") -> - | V16: =IF(T16=0,0,ROUND(C16/2*Global_Params!$B$31,0)) -> 0 | W16: =IF(T16=0,0,ROUND(D16/2*Global_Params!$B$31,0)) -> 0 | X16: =IF(T16=0,0,Global_Params!$B$32) -> 0 | Y16: =T16*Global_Params!$B$33 -> 0
A17: 2 | B17: 5 | C17: =MIN(Maps!$C$6-2,MAX(C16+2,ROUND(Maps!$C$6*Growth_Curve!$B$9/2,0)*2)) -> 24 | D17: =MIN(Maps!$D$6,MAX(D16,ROUND(Maps!$D$6*Growth_Curve!$B$9/2,0)*2)) -> 14 | E17: =C17*D17 -> 336 | F17: =E17-E16 -> 96 | G17: =ROUND(C17/2,0)+Global_Params!$B$16 -> 14 | H17: =ROUND(D17/2,0)+Global_Params!$B$16 -> 9 | I17: R | J17: =ROUND(Global_Params!$B$17*(1+Global_Params!$B$18*(B17-1))*Maps!$H$6,0) -> 189 | K17: =J17-L17-M17 -> 148 | L17: =ROUND(J17*(Global_Params!$B$19+(Global_Params!$B$20-Global_Params!$B$19)*(B17-1)/(Global_Params!$B$7-1)),0) -> 41 | M17: =ROUND(J17*IF(Maps!$G$6="Yes",Global_Params!$B$21,0),0) -> 0 | N17: =MAX(2,ROUND(E17/45,0)) -> 7 | O17: =MAX(1,MIN(Global_Params!$B$26,ROUND(F17/50,0))) -> 2 | P17: =ROUND(N17*0.6,0) -> 4 | Q17: =ROUND(E17/100*Global_Params!$B$25,0) -> 141 | R17: =Maps!$F$6 -> Flowers | S17: =Growth_Curve!$B$9 -> 0.79 | T17: =IF(B17<Global_Params!$B$30,0,MAX(1,ROUND(E17/260,0))) -> 1 | U17: =IF(T17=0,"-","L") -> L | V17: =IF(T17=0,0,ROUND(C17/2*Global_Params!$B$31,0)) -> 10 | W17: =IF(T17=0,0,ROUND(D17/2*Global_Params!$B$31,0)) -> 6 | X17: =IF(T17=0,0,Global_Params!$B$32) -> 4 | Y17: =T17*Global_Params!$B$33 -> 10
A18: 2 | B18: 6 | C18: =MIN(Maps!$C$6-2,MAX(C17+2,ROUND(Maps!$C$6*Growth_Curve!$B$10/2,0)*2)) -> 26 | D18: =MIN(Maps!$D$6,MAX(D17,ROUND(Maps!$D$6*Growth_Curve!$B$10/2,0)*2)) -> 16 | E18: =C18*D18 -> 416 | F18: =E18-E17 -> 80 | G18: =ROUND(C18/2,0)+Global_Params!$B$16 -> 15 | H18: =ROUND(D18/2,0)+Global_Params!$B$16 -> 10 | I18: T | J18: =ROUND(Global_Params!$B$17*(1+Global_Params!$B$18*(B18-1))*Maps!$H$6,0) -> 209 | K18: =J18-L18-M18 -> 158 | L18: =ROUND(J18*(Global_Params!$B$19+(Global_Params!$B$20-Global_Params!$B$19)*(B18-1)/(Global_Params!$B$7-1)),0) -> 51 | M18: =ROUND(J18*IF(Maps!$G$6="Yes",Global_Params!$B$21,0),0) -> 0 | N18: =MAX(2,ROUND(E18/45,0)) -> 9 | O18: =MAX(1,MIN(Global_Params!$B$26,ROUND(F18/50,0))) -> 2 | P18: =ROUND(N18*0.6,0) -> 5 | Q18: =ROUND(E18/100*Global_Params!$B$25,0) -> 175 | R18: =Maps!$F$6 -> Flowers | S18: =Growth_Curve!$B$10 -> 0.89 | T18: =IF(B18<Global_Params!$B$30,0,MAX(1,ROUND(E18/260,0))) -> 2 | U18: =IF(T18=0,"-","B") -> B | V18: =IF(T18=0,0,ROUND(C18/2*Global_Params!$B$31,0)) -> 10 | W18: =IF(T18=0,0,ROUND(D18/2*Global_Params!$B$31,0)) -> 6 | X18: =IF(T18=0,0,Global_Params!$B$32) -> 4 | Y18: =T18*Global_Params!$B$33 -> 20
A19: 2 | B19: 7 | C19: =MIN(Maps!$C$6-2,MAX(C18+2,ROUND(Maps!$C$6*Growth_Curve!$B$11/2,0)*2)) -> 28 | D19: =MIN(Maps!$D$6,MAX(D18,ROUND(Maps!$D$6*Growth_Curve!$B$11/2,0)*2)) -> 18 | E19: =C19*D19 -> 504 | F19: =E19-E18 -> 88 | G19: =ROUND(C19/2,0)+Global_Params!$B$16 -> 16 | H19: =ROUND(D19/2,0)+Global_Params!$B$16 -> 11 | I19: B | J19: =ROUND(Global_Params!$B$17*(1+Global_Params!$B$18*(B19-1))*Maps!$H$6,0) -> 229 | K19: =J19-L19-M19 -> 167 | L19: =ROUND(J19*(Global_Params!$B$19+(Global_Params!$B$20-Global_Params!$B$19)*(B19-1)/(Global_Params!$B$7-1)),0) -> 62 | M19: =ROUND(J19*IF(Maps!$G$6="Yes",Global_Params!$B$21,0),0) -> 0 | N19: =MAX(2,ROUND(E19/45,0)) -> 11 | O19: =MAX(1,MIN(Global_Params!$B$26,ROUND(F19/50,0))) -> 2 | P19: =ROUND(N19*0.6,0) -> 7 | Q19: =ROUND(E19/100*Global_Params!$B$25,0) -> 212 | R19: =Maps!$F$6 -> Flowers | S19: =Growth_Curve!$B$11 -> 0.96 | T19: =IF(B19<Global_Params!$B$30,0,MAX(1,ROUND(E19/260,0))) -> 2 | U19: =IF(T19=0,"-","T") -> T | V19: =IF(T19=0,0,ROUND(C19/2*Global_Params!$B$31,0)) -> 11 | W19: =IF(T19=0,0,ROUND(D19/2*Global_Params!$B$31,0)) -> 7 | X19: =IF(T19=0,0,Global_Params!$B$32) -> 4 | Y19: =T19*Global_Params!$B$33 -> 20
A20: 2 | B20: 8 | C20: =Maps!$C$6 -> 30 | D20: =Maps!$D$6 -> 18 | E20: =C20*D20 -> 540 | F20: =E20-E19 -> 36 | G20: =ROUND(C20/2,0)+Global_Params!$B$16 -> 17 | H20: =ROUND(D20/2,0)+Global_Params!$B$16 -> 11 | I20: L | J20: =ROUND(Global_Params!$B$17*(1+Global_Params!$B$18*(B20-1))*Maps!$H$6,0) -> 249 | K20: =J20-L20-M20 -> 174 | L20: =ROUND(J20*(Global_Params!$B$19+(Global_Params!$B$20-Global_Params!$B$19)*(B20-1)/(Global_Params!$B$7-1)),0) -> 75 | M20: =ROUND(J20*IF(Maps!$G$6="Yes",Global_Params!$B$21,0),0) -> 0 | N20: =MAX(2,ROUND(E20/45,0)) -> 12 | O20: =MAX(1,MIN(Global_Params!$B$26,ROUND(F20/50,0))) -> 1 | P20: =ROUND(N20*0.6,0) -> 7 | Q20: =ROUND(E20/100*Global_Params!$B$25,0) -> 227 | R20: =Maps!$F$6 -> Flowers | S20: =Growth_Curve!$B$12 -> 1 | T20: =IF(B20<Global_Params!$B$30,0,MAX(1,ROUND(E20/260,0))) -> 2 | U20: =IF(T20=0,"-","R") -> R | V20: =IF(T20=0,0,ROUND(C20/2*Global_Params!$B$31,0)) -> 12 | W20: =IF(T20=0,0,ROUND(D20/2*Global_Params!$B$31,0)) -> 7 | X20: =IF(T20=0,0,Global_Params!$B$32) -> 4 | Y20: =T20*Global_Params!$B$33 -> 20
A21: 3 | B21: 1 | C21: =MIN(Maps!$C$7-2,ROUND(Maps!$C$7*Growth_Curve!$B$5/2,0)*2) -> 14 | D21: =MIN(Maps!$D$7,ROUND(Maps!$D$7*Growth_Curve!$B$5/2,0)*2) -> 8 | E21: =C21*D21 -> 112 | F21: =E21 -> 112 | G21: =ROUND(C21/2,0)+Global_Params!$B$16 -> 9 | H21: =ROUND(D21/2,0)+Global_Params!$B$16 -> 6 | I21: L | J21: =ROUND(Global_Params!$B$17*(1+Global_Params!$B$18*(B21-1))*Maps!$H$7,0) -> 120 | K21: =J21-L21-M21 -> 90 | L21: =ROUND(J21*(Global_Params!$B$19+(Global_Params!$B$20-Global_Params!$B$19)*(B21-1)/(Global_Params!$B$7-1)),0) -> 12 | M21: =ROUND(J21*IF(Maps!$G$7="Yes",Global_Params!$B$21,0),0) -> 18 | N21: =MAX(2,ROUND(E21/45,0)) -> 2 | O21: =1 -> 1 | P21: =ROUND(N21*0.6,0) -> 1 | Q21: =ROUND(E21/100*Global_Params!$B$25,0) -> 47 | R21: =Maps!$F$7 -> Minerals | S21: =Growth_Curve!$B$5 -> 0.4 | T21: =IF(B21<Global_Params!$B$30,0,MAX(1,ROUND(E21/260,0))) -> 0 | U21: =IF(T21=0,"-","R") -> - | V21: =IF(T21=0,0,ROUND(C21/2*Global_Params!$B$31,0)) -> 0 | W21: =IF(T21=0,0,ROUND(D21/2*Global_Params!$B$31,0)) -> 0 | X21: =IF(T21=0,0,Global_Params!$B$32) -> 0 | Y21: =T21*Global_Params!$B$33 -> 0
A22: 3 | B22: 2 | C22: =MIN(Maps!$C$7-2,MAX(C21+2,ROUND(Maps!$C$7*Growth_Curve!$B$6/2,0)*2)) -> 16 | D22: =MIN(Maps!$D$7,MAX(D21,ROUND(Maps!$D$7*Growth_Curve!$B$6/2,0)*2)) -> 10 | E22: =C22*D22 -> 160 | F22: =E22-E21 -> 48 | G22: =ROUND(C22/2,0)+Global_Params!$B$16 -> 10 | H22: =ROUND(D22/2,0)+Global_Params!$B$16 -> 7 | I22: R | J22: =ROUND(Global_Params!$B$17*(1+Global_Params!$B$18*(B22-1))*Maps!$H$7,0) -> 142 | K22: =J22-L22-M22 -> 103 | L22: =ROUND(J22*(Global_Params!$B$19+(Global_Params!$B$20-Global_Params!$B$19)*(B22-1)/(Global_Params!$B$7-1)),0) -> 18 | M22: =ROUND(J22*IF(Maps!$G$7="Yes",Global_Params!$B$21,0),0) -> 21 | N22: =MAX(2,ROUND(E22/45,0)) -> 4 | O22: =MAX(1,MIN(Global_Params!$B$26,ROUND(F22/50,0))) -> 1 | P22: =ROUND(N22*0.6,0) -> 2 | Q22: =ROUND(E22/100*Global_Params!$B$25,0) -> 67 | R22: =Maps!$F$7 -> Minerals | S22: =Growth_Curve!$B$6 -> 0.46 | T22: =IF(B22<Global_Params!$B$30,0,MAX(1,ROUND(E22/260,0))) -> 0 | U22: =IF(T22=0,"-","L") -> - | V22: =IF(T22=0,0,ROUND(C22/2*Global_Params!$B$31,0)) -> 0 | W22: =IF(T22=0,0,ROUND(D22/2*Global_Params!$B$31,0)) -> 0 | X22: =IF(T22=0,0,Global_Params!$B$32) -> 0 | Y22: =T22*Global_Params!$B$33 -> 0
A23: 3 | B23: 3 | C23: =MIN(Maps!$C$7-2,MAX(C22+2,ROUND(Maps!$C$7*Growth_Curve!$B$7/2,0)*2)) -> 18 | D23: =MIN(Maps!$D$7,MAX(D22,ROUND(Maps!$D$7*Growth_Curve!$B$7/2,0)*2)) -> 10 | E23: =C23*D23 -> 180 | F23: =E23-E22 -> 20 | G23: =ROUND(C23/2,0)+Global_Params!$B$16 -> 11 | H23: =ROUND(D23/2,0)+Global_Params!$B$16 -> 7 | I23: L | J23: =ROUND(Global_Params!$B$17*(1+Global_Params!$B$18*(B23-1))*Maps!$H$7,0) -> 163 | K23: =J23-L23-M23 -> 113 | L23: =ROUND(J23*(Global_Params!$B$19+(Global_Params!$B$20-Global_Params!$B$19)*(B23-1)/(Global_Params!$B$7-1)),0) -> 26 | M23: =ROUND(J23*IF(Maps!$G$7="Yes",Global_Params!$B$21,0),0) -> 24 | N23: =MAX(2,ROUND(E23/45,0)) -> 4 | O23: =MAX(1,MIN(Global_Params!$B$26,ROUND(F23/50,0))) -> 1 | P23: =ROUND(N23*0.6,0) -> 2 | Q23: =ROUND(E23/100*Global_Params!$B$25,0) -> 76 | R23: =Maps!$F$7 -> Minerals | S23: =Growth_Curve!$B$7 -> 0.54 | T23: =IF(B23<Global_Params!$B$30,0,MAX(1,ROUND(E23/260,0))) -> 0 | U23: =IF(T23=0,"-","R") -> - | V23: =IF(T23=0,0,ROUND(C23/2*Global_Params!$B$31,0)) -> 0 | W23: =IF(T23=0,0,ROUND(D23/2*Global_Params!$B$31,0)) -> 0 | X23: =IF(T23=0,0,Global_Params!$B$32) -> 0 | Y23: =T23*Global_Params!$B$33 -> 0
A24: 3 | B24: 4 | C24: =MIN(Maps!$C$7-2,MAX(C23+2,ROUND(Maps!$C$7*Growth_Curve!$B$8/2,0)*2)) -> 22 | D24: =MIN(Maps!$D$7,MAX(D23,ROUND(Maps!$D$7*Growth_Curve!$B$8/2,0)*2)) -> 14 | E24: =C24*D24 -> 308 | F24: =E24-E23 -> 128 | G24: =ROUND(C24/2,0)+Global_Params!$B$16 -> 13 | H24: =ROUND(D24/2,0)+Global_Params!$B$16 -> 9 | I24: R | J24: =ROUND(Global_Params!$B$17*(1+Global_Params!$B$18*(B24-1))*Maps!$H$7,0) -> 185 | K24: =J24-L24-M24 -> 123 | L24: =ROUND(J24*(Global_Params!$B$19+(Global_Params!$B$20-Global_Params!$B$19)*(B24-1)/(Global_Params!$B$7-1)),0) -> 34 | M24: =ROUND(J24*IF(Maps!$G$7="Yes",Global_Params!$B$21,0),0) -> 28 | N24: =MAX(2,ROUND(E24/45,0)) -> 7 | O24: =MAX(1,MIN(Global_Params!$B$26,ROUND(F24/50,0))) -> 3 | P24: =ROUND(N24*0.6,0) -> 4 | Q24: =ROUND(E24/100*Global_Params!$B$25,0) -> 129 | R24: =Maps!$F$7 -> Minerals | S24: =Growth_Curve!$B$8 -> 0.66 | T24: =IF(B24<Global_Params!$B$30,0,MAX(1,ROUND(E24/260,0))) -> 0 | U24: =IF(T24=0,"-","L") -> - | V24: =IF(T24=0,0,ROUND(C24/2*Global_Params!$B$31,0)) -> 0 | W24: =IF(T24=0,0,ROUND(D24/2*Global_Params!$B$31,0)) -> 0 | X24: =IF(T24=0,0,Global_Params!$B$32) -> 0 | Y24: =T24*Global_Params!$B$33 -> 0
A25: 3 | B25: 5 | C25: =MIN(Maps!$C$7-2,MAX(C24+2,ROUND(Maps!$C$7*Growth_Curve!$B$9/2,0)*2)) -> 26 | D25: =MIN(Maps!$D$7,MAX(D24,ROUND(Maps!$D$7*Growth_Curve!$B$9/2,0)*2)) -> 16 | E25: =C25*D25 -> 416 | F25: =E25-E24 -> 108 | G25: =ROUND(C25/2,0)+Global_Params!$B$16 -> 15 | H25: =ROUND(D25/2,0)+Global_Params!$B$16 -> 10 | I25: T | J25: =ROUND(Global_Params!$B$17*(1+Global_Params!$B$18*(B25-1))*Maps!$H$7,0) -> 206 | K25: =J25-L25-M25 -> 131 | L25: =ROUND(J25*(Global_Params!$B$19+(Global_Params!$B$20-Global_Params!$B$19)*(B25-1)/(Global_Params!$B$7-1)),0) -> 44 | M25: =ROUND(J25*IF(Maps!$G$7="Yes",Global_Params!$B$21,0),0) -> 31 | N25: =MAX(2,ROUND(E25/45,0)) -> 9 | O25: =MAX(1,MIN(Global_Params!$B$26,ROUND(F25/50,0))) -> 2 | P25: =ROUND(N25*0.6,0) -> 5 | Q25: =ROUND(E25/100*Global_Params!$B$25,0) -> 175 | R25: =Maps!$F$7 -> Minerals | S25: =Growth_Curve!$B$9 -> 0.79 | T25: =IF(B25<Global_Params!$B$30,0,MAX(1,ROUND(E25/260,0))) -> 2 | U25: =IF(T25=0,"-","B") -> B | V25: =IF(T25=0,0,ROUND(C25/2*Global_Params!$B$31,0)) -> 10 | W25: =IF(T25=0,0,ROUND(D25/2*Global_Params!$B$31,0)) -> 6 | X25: =IF(T25=0,0,Global_Params!$B$32) -> 4 | Y25: =T25*Global_Params!$B$33 -> 20
A26: 3 | B26: 6 | C26: =MIN(Maps!$C$7-2,MAX(C25+2,ROUND(Maps!$C$7*Growth_Curve!$B$10/2,0)*2)) -> 30 | D26: =MIN(Maps!$D$7,MAX(D25,ROUND(Maps!$D$7*Growth_Curve!$B$10/2,0)*2)) -> 18 | E26: =C26*D26 -> 540 | F26: =E26-E25 -> 124 | G26: =ROUND(C26/2,0)+Global_Params!$B$16 -> 17 | H26: =ROUND(D26/2,0)+Global_Params!$B$16 -> 11 | I26: B | J26: =ROUND(Global_Params!$B$17*(1+Global_Params!$B$18*(B26-1))*Maps!$H$7,0) -> 228 | K26: =J26-L26-M26 -> 139 | L26: =ROUND(J26*(Global_Params!$B$19+(Global_Params!$B$20-Global_Params!$B$19)*(B26-1)/(Global_Params!$B$7-1)),0) -> 55 | M26: =ROUND(J26*IF(Maps!$G$7="Yes",Global_Params!$B$21,0),0) -> 34 | N26: =MAX(2,ROUND(E26/45,0)) -> 12 | O26: =MAX(1,MIN(Global_Params!$B$26,ROUND(F26/50,0))) -> 2 | P26: =ROUND(N26*0.6,0) -> 7 | Q26: =ROUND(E26/100*Global_Params!$B$25,0) -> 227 | R26: =Maps!$F$7 -> Minerals | S26: =Growth_Curve!$B$10 -> 0.89 | T26: =IF(B26<Global_Params!$B$30,0,MAX(1,ROUND(E26/260,0))) -> 2 | U26: =IF(T26=0,"-","T") -> T | V26: =IF(T26=0,0,ROUND(C26/2*Global_Params!$B$31,0)) -> 12 | W26: =IF(T26=0,0,ROUND(D26/2*Global_Params!$B$31,0)) -> 7 | X26: =IF(T26=0,0,Global_Params!$B$32) -> 4 | Y26: =T26*Global_Params!$B$33 -> 20
A27: 3 | B27: 7 | C27: =MIN(Maps!$C$7-2,MAX(C26+2,ROUND(Maps!$C$7*Growth_Curve!$B$11/2,0)*2)) -> 32 | D27: =MIN(Maps!$D$7,MAX(D26,ROUND(Maps!$D$7*Growth_Curve!$B$11/2,0)*2)) -> 20 | E27: =C27*D27 -> 640 | F27: =E27-E26 -> 100 | G27: =ROUND(C27/2,0)+Global_Params!$B$16 -> 18 | H27: =ROUND(D27/2,0)+Global_Params!$B$16 -> 12 | I27: L | J27: =ROUND(Global_Params!$B$17*(1+Global_Params!$B$18*(B27-1))*Maps!$H$7,0) -> 250 | K27: =J27-L27-M27 -> 144 | L27: =ROUND(J27*(Global_Params!$B$19+(Global_Params!$B$20-Global_Params!$B$19)*(B27-1)/(Global_Params!$B$7-1)),0) -> 68 | M27: =ROUND(J27*IF(Maps!$G$7="Yes",Global_Params!$B$21,0),0) -> 38 | N27: =MAX(2,ROUND(E27/45,0)) -> 14 | O27: =MAX(1,MIN(Global_Params!$B$26,ROUND(F27/50,0))) -> 2 | P27: =ROUND(N27*0.6,0) -> 8 | Q27: =ROUND(E27/100*Global_Params!$B$25,0) -> 269 | R27: =Maps!$F$7 -> Minerals | S27: =Growth_Curve!$B$11 -> 0.96 | T27: =IF(B27<Global_Params!$B$30,0,MAX(1,ROUND(E27/260,0))) -> 2 | U27: =IF(T27=0,"-","R") -> R | V27: =IF(T27=0,0,ROUND(C27/2*Global_Params!$B$31,0)) -> 13 | W27: =IF(T27=0,0,ROUND(D27/2*Global_Params!$B$31,0)) -> 8 | X27: =IF(T27=0,0,Global_Params!$B$32) -> 4 | Y27: =T27*Global_Params!$B$33 -> 20
A28: 3 | B28: 8 | C28: =Maps!$C$7 -> 34 | D28: =Maps!$D$7 -> 20 | E28: =C28*D28 -> 680 | F28: =E28-E27 -> 40 | G28: =ROUND(C28/2,0)+Global_Params!$B$16 -> 19 | H28: =ROUND(D28/2,0)+Global_Params!$B$16 -> 12 | I28: R | J28: =ROUND(Global_Params!$B$17*(1+Global_Params!$B$18*(B28-1))*Maps!$H$7,0) -> 271 | K28: =J28-L28-M28 -> 149 | L28: =ROUND(J28*(Global_Params!$B$19+(Global_Params!$B$20-Global_Params!$B$19)*(B28-1)/(Global_Params!$B$7-1)),0) -> 81 | M28: =ROUND(J28*IF(Maps!$G$7="Yes",Global_Params!$B$21,0),0) -> 41 | N28: =MAX(2,ROUND(E28/45,0)) -> 15 | O28: =MAX(1,MIN(Global_Params!$B$26,ROUND(F28/50,0))) -> 1 | P28: =ROUND(N28*0.6,0) -> 9 | Q28: =ROUND(E28/100*Global_Params!$B$25,0) -> 286 | R28: =Maps!$F$7 -> Minerals | S28: =Growth_Curve!$B$12 -> 1 | T28: =IF(B28<Global_Params!$B$30,0,MAX(1,ROUND(E28/260,0))) -> 3 | U28: =IF(T28=0,"-","L") -> L | V28: =IF(T28=0,0,ROUND(C28/2*Global_Params!$B$31,0)) -> 14 | W28: =IF(T28=0,0,ROUND(D28/2*Global_Params!$B$31,0)) -> 8 | X28: =IF(T28=0,0,Global_Params!$B$32) -> 4 | Y28: =T28*Global_Params!$B$33 -> 30
A29: 4 | B29: 1 | C29: =MIN(Maps!$C$8-2,ROUND(Maps!$C$8*Growth_Curve!$B$5/2,0)*2) -> 16 | D29: =MIN(Maps!$D$8,ROUND(Maps!$D$8*Growth_Curve!$B$5/2,0)*2) -> 8 | E29: =C29*D29 -> 128 | F29: =E29 -> 128 | G29: =ROUND(C29/2,0)+Global_Params!$B$16 -> 10 | H29: =ROUND(D29/2,0)+Global_Params!$B$16 -> 6 | I29: R | J29: =ROUND(Global_Params!$B$17*(1+Global_Params!$B$18*(B29-1))*Maps!$H$8,0) -> 130 | K29: =J29-L29-M29 -> 117 | L29: =ROUND(J29*(Global_Params!$B$19+(Global_Params!$B$20-Global_Params!$B$19)*(B29-1)/(Global_Params!$B$7-1)),0) -> 13 | M29: =ROUND(J29*IF(Maps!$G$8="Yes",Global_Params!$B$21,0),0) -> 0 | N29: =MAX(2,ROUND(E29/45,0)) -> 3 | O29: =1 -> 1 | P29: =ROUND(N29*0.6,0) -> 2 | Q29: =ROUND(E29/100*Global_Params!$B$25,0) -> 54 | R29: =Maps!$F$8 -> Minerals | S29: =Growth_Curve!$B$5 -> 0.4 | T29: =IF(B29<Global_Params!$B$30,0,MAX(1,ROUND(E29/260,0))) -> 0 | U29: =IF(T29=0,"-","L") -> - | V29: =IF(T29=0,0,ROUND(C29/2*Global_Params!$B$31,0)) -> 0 | W29: =IF(T29=0,0,ROUND(D29/2*Global_Params!$B$31,0)) -> 0 | X29: =IF(T29=0,0,Global_Params!$B$32) -> 0 | Y29: =T29*Global_Params!$B$33 -> 0
A30: 4 | B30: 2 | C30: =MIN(Maps!$C$8-2,MAX(C29+2,ROUND(Maps!$C$8*Growth_Curve!$B$6/2,0)*2)) -> 18 | D30: =MIN(Maps!$D$8,MAX(D29,ROUND(Maps!$D$8*Growth_Curve!$B$6/2,0)*2)) -> 10 | E30: =C30*D30 -> 180 | F30: =E30-E29 -> 52 | G30: =ROUND(C30/2,0)+Global_Params!$B$16 -> 11 | H30: =ROUND(D30/2,0)+Global_Params!$B$16 -> 7 | I30: L | J30: =ROUND(Global_Params!$B$17*(1+Global_Params!$B$18*(B30-1))*Maps!$H$8,0) -> 153 | K30: =J30-L30-M30 -> 133 | L30: =ROUND(J30*(Global_Params!$B$19+(Global_Params!$B$20-Global_Params!$B$19)*(B30-1)/(Global_Params!$B$7-1)),0) -> 20 | M30: =ROUND(J30*IF(Maps!$G$8="Yes",Global_Params!$B$21,0),0) -> 0 | N30: =MAX(2,ROUND(E30/45,0)) -> 4 | O30: =MAX(1,MIN(Global_Params!$B$26,ROUND(F30/50,0))) -> 1 | P30: =ROUND(N30*0.6,0) -> 2 | Q30: =ROUND(E30/100*Global_Params!$B$25,0) -> 76 | R30: =Maps!$F$8 -> Minerals | S30: =Growth_Curve!$B$6 -> 0.46 | T30: =IF(B30<Global_Params!$B$30,0,MAX(1,ROUND(E30/260,0))) -> 0 | U30: =IF(T30=0,"-","R") -> - | V30: =IF(T30=0,0,ROUND(C30/2*Global_Params!$B$31,0)) -> 0 | W30: =IF(T30=0,0,ROUND(D30/2*Global_Params!$B$31,0)) -> 0 | X30: =IF(T30=0,0,Global_Params!$B$32) -> 0 | Y30: =T30*Global_Params!$B$33 -> 0
A31: 4 | B31: 3 | C31: =MIN(Maps!$C$8-2,MAX(C30+2,ROUND(Maps!$C$8*Growth_Curve!$B$7/2,0)*2)) -> 22 | D31: =MIN(Maps!$D$8,MAX(D30,ROUND(Maps!$D$8*Growth_Curve!$B$7/2,0)*2)) -> 12 | E31: =C31*D31 -> 264 | F31: =E31-E30 -> 84 | G31: =ROUND(C31/2,0)+Global_Params!$B$16 -> 13 | H31: =ROUND(D31/2,0)+Global_Params!$B$16 -> 8 | I31: R | J31: =ROUND(Global_Params!$B$17*(1+Global_Params!$B$18*(B31-1))*Maps!$H$8,0) -> 177 | K31: =J31-L31-M31 -> 149 | L31: =ROUND(J31*(Global_Params!$B$19+(Global_Params!$B$20-Global_Params!$B$19)*(B31-1)/(Global_Params!$B$7-1)),0) -> 28 | M31: =ROUND(J31*IF(Maps!$G$8="Yes",Global_Params!$B$21,0),0) -> 0 | N31: =MAX(2,ROUND(E31/45,0)) -> 6 | O31: =MAX(1,MIN(Global_Params!$B$26,ROUND(F31/50,0))) -> 2 | P31: =ROUND(N31*0.6,0) -> 4 | Q31: =ROUND(E31/100*Global_Params!$B$25,0) -> 111 | R31: =Maps!$F$8 -> Minerals | S31: =Growth_Curve!$B$7 -> 0.54 | T31: =IF(B31<Global_Params!$B$30,0,MAX(1,ROUND(E31/260,0))) -> 0 | U31: =IF(T31=0,"-","L") -> - | V31: =IF(T31=0,0,ROUND(C31/2*Global_Params!$B$31,0)) -> 0 | W31: =IF(T31=0,0,ROUND(D31/2*Global_Params!$B$31,0)) -> 0 | X31: =IF(T31=0,0,Global_Params!$B$32) -> 0 | Y31: =T31*Global_Params!$B$33 -> 0
A32: 4 | B32: 4 | C32: =MIN(Maps!$C$8-2,MAX(C31+2,ROUND(Maps!$C$8*Growth_Curve!$B$8/2,0)*2)) -> 26 | D32: =MIN(Maps!$D$8,MAX(D31,ROUND(Maps!$D$8*Growth_Curve!$B$8/2,0)*2)) -> 14 | E32: =C32*D32 -> 364 | F32: =E32-E31 -> 100 | G32: =ROUND(C32/2,0)+Global_Params!$B$16 -> 15 | H32: =ROUND(D32/2,0)+Global_Params!$B$16 -> 9 | I32: T | J32: =ROUND(Global_Params!$B$17*(1+Global_Params!$B$18*(B32-1))*Maps!$H$8,0) -> 200 | K32: =J32-L32-M32 -> 163 | L32: =ROUND(J32*(Global_Params!$B$19+(Global_Params!$B$20-Global_Params!$B$19)*(B32-1)/(Global_Params!$B$7-1)),0) -> 37 | M32: =ROUND(J32*IF(Maps!$G$8="Yes",Global_Params!$B$21,0),0) -> 0 | N32: =MAX(2,ROUND(E32/45,0)) -> 8 | O32: =MAX(1,MIN(Global_Params!$B$26,ROUND(F32/50,0))) -> 2 | P32: =ROUND(N32*0.6,0) -> 5 | Q32: =ROUND(E32/100*Global_Params!$B$25,0) -> 153 | R32: =Maps!$F$8 -> Minerals | S32: =Growth_Curve!$B$8 -> 0.66 | T32: =IF(B32<Global_Params!$B$30,0,MAX(1,ROUND(E32/260,0))) -> 0 | U32: =IF(T32=0,"-","B") -> - | V32: =IF(T32=0,0,ROUND(C32/2*Global_Params!$B$31,0)) -> 0 | W32: =IF(T32=0,0,ROUND(D32/2*Global_Params!$B$31,0)) -> 0 | X32: =IF(T32=0,0,Global_Params!$B$32) -> 0 | Y32: =T32*Global_Params!$B$33 -> 0
A33: 4 | B33: 5 | C33: =MIN(Maps!$C$8-2,MAX(C32+2,ROUND(Maps!$C$8*Growth_Curve!$B$9/2,0)*2)) -> 32 | D33: =MIN(Maps!$D$8,MAX(D32,ROUND(Maps!$D$8*Growth_Curve!$B$9/2,0)*2)) -> 18 | E33: =C33*D33 -> 576 | F33: =E33-E32 -> 212 | G33: =ROUND(C33/2,0)+Global_Params!$B$16 -> 18 | H33: =ROUND(D33/2,0)+Global_Params!$B$16 -> 11 | I33: B | J33: =ROUND(Global_Params!$B$17*(1+Global_Params!$B$18*(B33-1))*Maps!$H$8,0) -> 224 | K33: =J33-L33-M33 -> 176 | L33: =ROUND(J33*(Global_Params!$B$19+(Global_Params!$B$20-Global_Params!$B$19)*(B33-1)/(Global_Params!$B$7-1)),0) -> 48 | M33: =ROUND(J33*IF(Maps!$G$8="Yes",Global_Params!$B$21,0),0) -> 0 | N33: =MAX(2,ROUND(E33/45,0)) -> 13 | O33: =MAX(1,MIN(Global_Params!$B$26,ROUND(F33/50,0))) -> 3 | P33: =ROUND(N33*0.6,0) -> 8 | Q33: =ROUND(E33/100*Global_Params!$B$25,0) -> 242 | R33: =Maps!$F$8 -> Minerals | S33: =Growth_Curve!$B$9 -> 0.79 | T33: =IF(B33<Global_Params!$B$30,0,MAX(1,ROUND(E33/260,0))) -> 2 | U33: =IF(T33=0,"-","T") -> T | V33: =IF(T33=0,0,ROUND(C33/2*Global_Params!$B$31,0)) -> 13 | W33: =IF(T33=0,0,ROUND(D33/2*Global_Params!$B$31,0)) -> 7 | X33: =IF(T33=0,0,Global_Params!$B$32) -> 4 | Y33: =T33*Global_Params!$B$33 -> 20
A34: 4 | B34: 6 | C34: =MIN(Maps!$C$8-2,MAX(C33+2,ROUND(Maps!$C$8*Growth_Curve!$B$10/2,0)*2)) -> 36 | D34: =MIN(Maps!$D$8,MAX(D33,ROUND(Maps!$D$8*Growth_Curve!$B$10/2,0)*2)) -> 20 | E34: =C34*D34 -> 720 | F34: =E34-E33 -> 144 | G34: =ROUND(C34/2,0)+Global_Params!$B$16 -> 20 | H34: =ROUND(D34/2,0)+Global_Params!$B$16 -> 12 | I34: L | J34: =ROUND(Global_Params!$B$17*(1+Global_Params!$B$18*(B34-1))*Maps!$H$8,0) -> 247 | K34: =J34-L34-M34 -> 187 | L34: =ROUND(J34*(Global_Params!$B$19+(Global_Params!$B$20-Global_Params!$B$19)*(B34-1)/(Global_Params!$B$7-1)),0) -> 60 | M34: =ROUND(J34*IF(Maps!$G$8="Yes",Global_Params!$B$21,0),0) -> 0 | N34: =MAX(2,ROUND(E34/45,0)) -> 16 | O34: =MAX(1,MIN(Global_Params!$B$26,ROUND(F34/50,0))) -> 3 | P34: =ROUND(N34*0.6,0) -> 10 | Q34: =ROUND(E34/100*Global_Params!$B$25,0) -> 302 | R34: =Maps!$F$8 -> Minerals | S34: =Growth_Curve!$B$10 -> 0.89 | T34: =IF(B34<Global_Params!$B$30,0,MAX(1,ROUND(E34/260,0))) -> 3 | U34: =IF(T34=0,"-","R") -> R | V34: =IF(T34=0,0,ROUND(C34/2*Global_Params!$B$31,0)) -> 14 | W34: =IF(T34=0,0,ROUND(D34/2*Global_Params!$B$31,0)) -> 8 | X34: =IF(T34=0,0,Global_Params!$B$32) -> 4 | Y34: =T34*Global_Params!$B$33 -> 30
A35: 4 | B35: 7 | C35: =MIN(Maps!$C$8-2,MAX(C34+2,ROUND(Maps!$C$8*Growth_Curve!$B$11/2,0)*2)) -> 38 | D35: =MIN(Maps!$D$8,MAX(D34,ROUND(Maps!$D$8*Growth_Curve!$B$11/2,0)*2)) -> 22 | E35: =C35*D35 -> 836 | F35: =E35-E34 -> 116 | G35: =ROUND(C35/2,0)+Global_Params!$B$16 -> 21 | H35: =ROUND(D35/2,0)+Global_Params!$B$16 -> 13 | I35: R | J35: =ROUND(Global_Params!$B$17*(1+Global_Params!$B$18*(B35-1))*Maps!$H$8,0) -> 270 | K35: =J35-L35-M35 -> 197 | L35: =ROUND(J35*(Global_Params!$B$19+(Global_Params!$B$20-Global_Params!$B$19)*(B35-1)/(Global_Params!$B$7-1)),0) -> 73 | M35: =ROUND(J35*IF(Maps!$G$8="Yes",Global_Params!$B$21,0),0) -> 0 | N35: =MAX(2,ROUND(E35/45,0)) -> 19 | O35: =MAX(1,MIN(Global_Params!$B$26,ROUND(F35/50,0))) -> 2 | P35: =ROUND(N35*0.6,0) -> 11 | Q35: =ROUND(E35/100*Global_Params!$B$25,0) -> 351 | R35: =Maps!$F$8 -> Minerals | S35: =Growth_Curve!$B$11 -> 0.96 | T35: =IF(B35<Global_Params!$B$30,0,MAX(1,ROUND(E35/260,0))) -> 3 | U35: =IF(T35=0,"-","L") -> L | V35: =IF(T35=0,0,ROUND(C35/2*Global_Params!$B$31,0)) -> 15 | W35: =IF(T35=0,0,ROUND(D35/2*Global_Params!$B$31,0)) -> 9 | X35: =IF(T35=0,0,Global_Params!$B$32) -> 4 | Y35: =T35*Global_Params!$B$33 -> 30
A36: 4 | B36: 8 | C36: =Maps!$C$8 -> 40 | D36: =Maps!$D$8 -> 22 | E36: =C36*D36 -> 880 | F36: =E36-E35 -> 44 | G36: =ROUND(C36/2,0)+Global_Params!$B$16 -> 22 | H36: =ROUND(D36/2,0)+Global_Params!$B$16 -> 13 | I36: L | J36: =ROUND(Global_Params!$B$17*(1+Global_Params!$B$18*(B36-1))*Maps!$H$8,0) -> 294 | K36: =J36-L36-M36 -> 206 | L36: =ROUND(J36*(Global_Params!$B$19+(Global_Params!$B$20-Global_Params!$B$19)*(B36-1)/(Global_Params!$B$7-1)),0) -> 88 | M36: =ROUND(J36*IF(Maps!$G$8="Yes",Global_Params!$B$21,0),0) -> 0 | N36: =MAX(2,ROUND(E36/45,0)) -> 20 | O36: =MAX(1,MIN(Global_Params!$B$26,ROUND(F36/50,0))) -> 1 | P36: =ROUND(N36*0.6,0) -> 12 | Q36: =ROUND(E36/100*Global_Params!$B$25,0) -> 370 | R36: =Maps!$F$8 -> Minerals | S36: =Growth_Curve!$B$12 -> 1 | T36: =IF(B36<Global_Params!$B$30,0,MAX(1,ROUND(E36/260,0))) -> 3 | U36: =IF(T36=0,"-","R") -> R | V36: =IF(T36=0,0,ROUND(C36/2*Global_Params!$B$31,0)) -> 16 | W36: =IF(T36=0,0,ROUND(D36/2*Global_Params!$B$31,0)) -> 9 | X36: =IF(T36=0,0,Global_Params!$B$32) -> 4 | Y36: =T36*Global_Params!$B$33 -> 30
A37: 5 | B37: 1 | C37: =MIN(Maps!$C$9-2,ROUND(Maps!$C$9*Growth_Curve!$B$5/2,0)*2) -> 18 | D37: =MIN(Maps!$D$9,ROUND(Maps!$D$9*Growth_Curve!$B$5/2,0)*2) -> 10 | E37: =C37*D37 -> 180 | F37: =E37 -> 180 | G37: =ROUND(C37/2,0)+Global_Params!$B$16 -> 11 | H37: =ROUND(D37/2,0)+Global_Params!$B$16 -> 7 | I37: L | J37: =ROUND(Global_Params!$B$17*(1+Global_Params!$B$18*(B37-1))*Maps!$H$9,0) -> 140 | K37: =J37-L37-M37 -> 105 | L37: =ROUND(J37*(Global_Params!$B$19+(Global_Params!$B$20-Global_Params!$B$19)*(B37-1)/(Global_Params!$B$7-1)),0) -> 14 | M37: =ROUND(J37*IF(Maps!$G$9="Yes",Global_Params!$B$21,0),0) -> 21 | N37: =MAX(2,ROUND(E37/45,0)) -> 4 | O37: =1 -> 1 | P37: =ROUND(N37*0.6,0) -> 2 | Q37: =ROUND(E37/100*Global_Params!$B$25,0) -> 76 | R37: =Maps!$F$9 -> Crystals | S37: =Growth_Curve!$B$5 -> 0.4 | T37: =IF(B37<Global_Params!$B$30,0,MAX(1,ROUND(E37/260,0))) -> 0 | U37: =IF(T37=0,"-","R") -> - | V37: =IF(T37=0,0,ROUND(C37/2*Global_Params!$B$31,0)) -> 0 | W37: =IF(T37=0,0,ROUND(D37/2*Global_Params!$B$31,0)) -> 0 | X37: =IF(T37=0,0,Global_Params!$B$32) -> 0 | Y37: =T37*Global_Params!$B$33 -> 0
A38: 5 | B38: 2 | C38: =MIN(Maps!$C$9-2,MAX(C37+2,ROUND(Maps!$C$9*Growth_Curve!$B$6/2,0)*2)) -> 20 | D38: =MIN(Maps!$D$9,MAX(D37,ROUND(Maps!$D$9*Growth_Curve!$B$6/2,0)*2)) -> 12 | E38: =C38*D38 -> 240 | F38: =E38-E37 -> 60 | G38: =ROUND(C38/2,0)+Global_Params!$B$16 -> 12 | H38: =ROUND(D38/2,0)+Global_Params!$B$16 -> 8 | I38: R | J38: =ROUND(Global_Params!$B$17*(1+Global_Params!$B$18*(B38-1))*Maps!$H$9,0) -> 165 | K38: =J38-L38-M38 -> 119 | L38: =ROUND(J38*(Global_Params!$B$19+(Global_Params!$B$20-Global_Params!$B$19)*(B38-1)/(Global_Params!$B$7-1)),0) -> 21 | M38: =ROUND(J38*IF(Maps!$G$9="Yes",Global_Params!$B$21,0),0) -> 25 | N38: =MAX(2,ROUND(E38/45,0)) -> 5 | O38: =MAX(1,MIN(Global_Params!$B$26,ROUND(F38/50,0))) -> 1 | P38: =ROUND(N38*0.6,0) -> 3 | Q38: =ROUND(E38/100*Global_Params!$B$25,0) -> 101 | R38: =Maps!$F$9 -> Crystals | S38: =Growth_Curve!$B$6 -> 0.46 | T38: =IF(B38<Global_Params!$B$30,0,MAX(1,ROUND(E38/260,0))) -> 0 | U38: =IF(T38=0,"-","L") -> - | V38: =IF(T38=0,0,ROUND(C38/2*Global_Params!$B$31,0)) -> 0 | W38: =IF(T38=0,0,ROUND(D38/2*Global_Params!$B$31,0)) -> 0 | X38: =IF(T38=0,0,Global_Params!$B$32) -> 0 | Y38: =T38*Global_Params!$B$33 -> 0
A39: 5 | B39: 3 | C39: =MIN(Maps!$C$9-2,MAX(C38+2,ROUND(Maps!$C$9*Growth_Curve!$B$7/2,0)*2)) -> 24 | D39: =MIN(Maps!$D$9,MAX(D38,ROUND(Maps!$D$9*Growth_Curve!$B$7/2,0)*2)) -> 12 | E39: =C39*D39 -> 288 | F39: =E39-E38 -> 48 | G39: =ROUND(C39/2,0)+Global_Params!$B$16 -> 14 | H39: =ROUND(D39/2,0)+Global_Params!$B$16 -> 8 | I39: T | J39: =ROUND(Global_Params!$B$17*(1+Global_Params!$B$18*(B39-1))*Maps!$H$9,0) -> 190 | K39: =J39-L39-M39 -> 131 | L39: =ROUND(J39*(Global_Params!$B$19+(Global_Params!$B$20-Global_Params!$B$19)*(B39-1)/(Global_Params!$B$7-1)),0) -> 30 | M39: =ROUND(J39*IF(Maps!$G$9="Yes",Global_Params!$B$21,0),0) -> 29 | N39: =MAX(2,ROUND(E39/45,0)) -> 6 | O39: =MAX(1,MIN(Global_Params!$B$26,ROUND(F39/50,0))) -> 1 | P39: =ROUND(N39*0.6,0) -> 4 | Q39: =ROUND(E39/100*Global_Params!$B$25,0) -> 121 | R39: =Maps!$F$9 -> Crystals | S39: =Growth_Curve!$B$7 -> 0.54 | T39: =IF(B39<Global_Params!$B$30,0,MAX(1,ROUND(E39/260,0))) -> 0 | U39: =IF(T39=0,"-","B") -> - | V39: =IF(T39=0,0,ROUND(C39/2*Global_Params!$B$31,0)) -> 0 | W39: =IF(T39=0,0,ROUND(D39/2*Global_Params!$B$31,0)) -> 0 | X39: =IF(T39=0,0,Global_Params!$B$32) -> 0 | Y39: =T39*Global_Params!$B$33 -> 0
A40: 5 | B40: 4 | C40: =MIN(Maps!$C$9-2,MAX(C39+2,ROUND(Maps!$C$9*Growth_Curve!$B$8/2,0)*2)) -> 30 | D40: =MIN(Maps!$D$9,MAX(D39,ROUND(Maps!$D$9*Growth_Curve!$B$8/2,0)*2)) -> 16 | E40: =C40*D40 -> 480 | F40: =E40-E39 -> 192 | G40: =ROUND(C40/2,0)+Global_Params!$B$16 -> 17 | H40: =ROUND(D40/2,0)+Global_Params!$B$16 -> 10 | I40: B | J40: =ROUND(Global_Params!$B$17*(1+Global_Params!$B$18*(B40-1))*Maps!$H$9,0) -> 216 | K40: =J40-L40-M40 -> 144 | L40: =ROUND(J40*(Global_Params!$B$19+(Global_Params!$B$20-Global_Params!$B$19)*(B40-1)/(Global_Params!$B$7-1)),0) -> 40 | M40: =ROUND(J40*IF(Maps!$G$9="Yes",Global_Params!$B$21,0),0) -> 32 | N40: =MAX(2,ROUND(E40/45,0)) -> 11 | O40: =MAX(1,MIN(Global_Params!$B$26,ROUND(F40/50,0))) -> 3 | P40: =ROUND(N40*0.6,0) -> 7 | Q40: =ROUND(E40/100*Global_Params!$B$25,0) -> 202 | R40: =Maps!$F$9 -> Crystals | S40: =Growth_Curve!$B$8 -> 0.66 | T40: =IF(B40<Global_Params!$B$30,0,MAX(1,ROUND(E40/260,0))) -> 0 | U40: =IF(T40=0,"-","T") -> - | V40: =IF(T40=0,0,ROUND(C40/2*Global_Params!$B$31,0)) -> 0 | W40: =IF(T40=0,0,ROUND(D40/2*Global_Params!$B$31,0)) -> 0 | X40: =IF(T40=0,0,Global_Params!$B$32) -> 0 | Y40: =T40*Global_Params!$B$33 -> 0
A41: 5 | B41: 5 | C41: =MIN(Maps!$C$9-2,MAX(C40+2,ROUND(Maps!$C$9*Growth_Curve!$B$9/2,0)*2)) -> 34 | D41: =MIN(Maps!$D$9,MAX(D40,ROUND(Maps!$D$9*Growth_Curve!$B$9/2,0)*2)) -> 18 | E41: =C41*D41 -> 612 | F41: =E41-E40 -> 132 | G41: =ROUND(C41/2,0)+Global_Params!$B$16 -> 19 | H41: =ROUND(D41/2,0)+Global_Params!$B$16 -> 11 | I41: L | J41: =ROUND(Global_Params!$B$17*(1+Global_Params!$B$18*(B41-1))*Maps!$H$9,0) -> 241 | K41: =J41-L41-M41 -> 153 | L41: =ROUND(J41*(Global_Params!$B$19+(Global_Params!$B$20-Global_Params!$B$19)*(B41-1)/(Global_Params!$B$7-1)),0) -> 52 | M41: =ROUND(J41*IF(Maps!$G$9="Yes",Global_Params!$B$21,0),0) -> 36 | N41: =MAX(2,ROUND(E41/45,0)) -> 14 | O41: =MAX(1,MIN(Global_Params!$B$26,ROUND(F41/50,0))) -> 3 | P41: =ROUND(N41*0.6,0) -> 8 | Q41: =ROUND(E41/100*Global_Params!$B$25,0) -> 257 | R41: =Maps!$F$9 -> Crystals | S41: =Growth_Curve!$B$9 -> 0.79 | T41: =IF(B41<Global_Params!$B$30,0,MAX(1,ROUND(E41/260,0))) -> 2 | U41: =IF(T41=0,"-","R") -> R | V41: =IF(T41=0,0,ROUND(C41/2*Global_Params!$B$31,0)) -> 14 | W41: =IF(T41=0,0,ROUND(D41/2*Global_Params!$B$31,0)) -> 7 | X41: =IF(T41=0,0,Global_Params!$B$32) -> 4 | Y41: =T41*Global_Params!$B$33 -> 20
...

Sheet Score_Model
A1: Map Score Model
A2: Worked example. Map 5 / Faction 5 (the greed faction). Edit the blue cells.
A4: Item | B4: Value | C4: Notes
A5: INPUTS
A6: Map_ID | B6: 5 | C6: Row 9 in Maps.
A7: Faction_ID | B7: 5 | C7: Row 9 in Factions.
